Workbook
Name SECTOR: 'PS1'!$F$1

Sheet All_India_Index_Upto_April23 (1
A1: Sector | B1: Year | C1: Month | D1: Cereals and products | E1: Meat and fish | F1: Egg | G1: Milk and products | H1: Oils and fats | I1: Fruits | J1: Vegetables | K1: Pulses and products | L1: Sugar and Confectionery | M1: Spices | N1: Non-alcoholic beverages | O1: Prepared meals, snacks, sweets etc. | P1: Food and beverages | Q1: Pan, tobacco and intoxicants | R1: Clothing | S1: Footwear | T1: Clothing and footwear | U1: Housing | V1: Fuel and light | W1: Household goods and services | X1: Health | Y1: Transport and communication | Z1: Recreation and amusement | AA1: Education | AB1: Personal care and effects | AC1: Miscellaneous | AD1: General index
A2: Rural | B2: 2013 | C2: January | D2: 107.5 | E2: 106.3 | F2: 108.1 | G2: 104.9 | H2: 106.1 | I2: 103.9 | J2: 101.9 | K2: 106.1 | L2: 106.8 | M2: 103.1 | N2: 104.8 | O2: 106.7 | P2: 105.5 | Q2: 105.1 | R2: 106.5 | S2: 105.8 | T2: 106.4 | U2: NA | V2: 105.5 | W2: 104.8 | X2: 104 | Y2: 103.3 | Z2: 103.4 | AA2: 103.8 | AB2: 104.7 | AC2: 104 | AD2: 105.1
A3: Urban | B3: 2013 | C3: January | D3: 110.5 | E3: 109.1 | F3: 113 | G3: 103.6 | H3: 103.4 | I3: 102.3 | J3: 102.9 | K3: 105.8 | L3: 105.1 | M3: 101.8 | N3: 105.1 | O3: 107.9 | P3: 105.9 | Q3: 105.2 | R3: 105.9 | S3: 105 | T3: 105.8 | U3: 100.3 | V3: 105.4 | W3: 104.8 | X3: 104.1 | Y3: 103.2 | Z3: 102.9 | AA3: 103.5 | AB3: 104.3 | AC3: 103.7 | AD3: 104
A4: Rural+Urban | B4: 2013 | C4: January | D4: 108.4 | E4: 107.3 | F4: 110 | G4: 104.4 | H4: 105.1 | I4: 103.2 | J4: 102.2 | K4: 106 | L4: 106.2 | M4: 102.7 | N4: 104.9 | O4: 107.3 | P4: 105.6 | Q4: 105.1 | R4: 106.3 | S4: 105.5 | T4: 106.2 | U4: 100.3 | V4: 105.5 | W4: 104.8 | X4: 104 | Y4: 103.2 | Z4: 103.1 | AA4: 103.6 | AB4: 104.5 | AC4: 103.9 | AD4: 104.6
A5: Rural | B5: 2013 | C5: February | D5: 109.2 | E5: 108.7 | F5: 110.2 | G5: 105.4 | H5: 106.7 | I5: 104 | J5: 102.4 | K5: 105.9 | L5: 105.7 | M5: 103.1 | N5: 105.1 | O5: 107.7 | P5: 106.3 | Q5: 105.6 | R5: 107.1 | S5: 106.3 | T5: 107 | U5: NA | V5: 106.2 | W5: 105.2 | X5: 104.4 | Y5: 103.9 | Z5: 104 | AA5: 104.1 | AB5: 104.6 | AC5: 104.4 | AD5: 105.8
A6: Urban | B6: 2013 | C6: February | D6: 112.9 | E6: 112.9 | F6: 116.9 | G6: 104 | H6: 103.5 | I6: 103.1 | J6: 104.9 | K6: 104.1 | L6: 103.8 | M6: 102.3 | N6: 106 | O6: 109 | P6: 107.2 | Q6: 106 | R6: 106.6 | S6: 105.5 | T6: 106.4 | U6: 100.4 | V6: 105.7 | W6: 105.2 | X6: 104.7 | Y6: 104.4 | Z6: 103.3 | AA6: 103.7 | AB6: 104.3 | AC6: 104.3 | AD6: 104.7
A7: Rural+Urban | B7: 2013 | C7: February | D7: 110.4 | E7: 110.2 | F7: 112.8 | G7: 104.9 | H7: 105.5 | I7: 103.6 | J7: 103.2 | K7: 105.3 | L7: 105.1 | M7: 102.8 | N7: 105.5 | O7: 108.3 | P7: 106.6 | Q7: 105.7 | R7: 106.9 | S7: 106 | T7: 106.8 | U7: 100.4 | V7: 106 | W7: 105.2 | X7: 104.5 | Y7: 104.2 | Z7: 103.6 | AA7: 103.9 | AB7: 104.5 | AC7: 104.4 | AD7: 105.3
A8: Rural | B8: 2013 | C8: March | D8: 110.2 | E8: 108.8 | F8: 109.9 | G8: 105.6 | H8: 106.2 | I8: 105.7 | J8: 101.4 | K8: 105.7 | L8: 105 | M8: 103.3 | N8: 105.6 | O8: 108.2 | P8: 106.6 | Q8: 106.5 | R8: 107.6 | S8: 106.8 | T8: 107.5 | U8: NA | V8: 106.1 | W8: 105.6 | X8: 104.7 | Y8: 104.6 | Z8: 104 | AA8: 104.3 | AB8: 104.3 | AC8: 104.6 | AD8: 106
A9: Urban | B9: 2013 | C9: March | D9: 113.9 | E9: 111.4 | F9: 113.2 | G9: 104.3 | H9: 102.7 | I9: 104.9 | J9: 103.8 | K9: 103.5 | L9: 102.6 | M9: 102.4 | N9: 107 | O9: 109.8 | P9: 107.3 | Q9: 106.8 | R9: 107.2 | S9: 106 | T9: 107 | U9: 100.4 | V9: 106 | W9: 105.7 | X9: 105.2 | Y9: 105.5 | Z9: 103.5 | AA9: 103.8 | AB9: 104.2 | AC9: 104.9 | AD9: 105
A10: Rural+Urban | B10: 2013 | C10: March | D10: 111.4 | E10: 109.7 | F10: 111.2 | G10: 105.1 | H10: 104.9 | I10: 105.3 | J10: 102.2 | K10: 105 | L10: 104.2 | M10: 103 | N10: 106.2 | O10: 108.9 | P10: 106.9 | Q10: 106.6 | R10: 107.4 | S10: 106.5 | T10: 107.3 | U10: 100.4 | V10: 106.1 | W10: 105.6 | X10: 104.9 | Y10: 105.1 | Z10: 103.7 | AA10: 104 | AB10: 104.3 | AC10: 104.7 | AD10: 105.5
A11: Rural | B11: 2013 | C11: April | D11: 110.2 | E11: 109.5 | F11: 106.9 | G11: 106.3 | H11: 105.7 | I11: 108.3 | J11: 103.4 | K11: 105.7 | L11: 104.2 | M11: 103.2 | N11: 106.5 | O11: 108.8 | P11: 107.1 | Q11: 107.1 | R11: 108.1 | S11: 107.4 | T11: 108 | U11: NA | V11: 106.5 | W11: 106.1 | X11: 105.1 | Y11: 104.4 | Z11: 104.5 | AA11: 104.8 | AB11: 102.7 | AC11: 104.6 | AD11: 106.4
A12: Urban | B12: 2013 | C12: April | D12: 114.6 | E12: 113.4 | F12: 106 | G12: 104.7 | H12: 102.1 | I12: 109.5 | J12: 109.7 | K12: 104.6 | L12: 102 | M12: 103.5 | N12: 108.2 | O12: 110.6 | P12: 108.8 | Q12: 108.5 | R12: 107.9 | S12: 106.4 | T12: 107.7 | U12: 100.5 | V12: 106.4 | W12: 106.5 | X12: 105.7 | Y12: 105 | Z12: 104 | AA12: 105.2 | AB12: 103.2 | AC12: 105.1 | AD12: 105.7
A13: Rural+Urban | B13: 2013 | C13: April | D13: 111.6 | E13: 110.9 | F13: 106.6 | G13: 105.7 | H13: 104.4 | I13: 108.9 | J13: 105.5 | K13: 105.3 | L13: 103.5 | M13: 103.3 | N13: 107.2 | O13: 109.6 | P13: 107.7 | Q13: 107.5 | R13: 108 | S13: 107 | T13: 107.9 | U13: 100.5 | V13: 106.5 | W13: 106.3 | X13: 105.3 | Y13: 104.7 | Z13: 104.2 | AA13: 105 | AB13: 102.9 | AC13: 104.8 | AD13: 106.1
A14: Rural | B14: 2013 | C14: May | D14: 110.9 | E14: 109.8 | F14: 105.9 | G14: 107.5 | H14: 105.3 | I14: 108.1 | J14: 107.3 | K14: 106.1 | L14: 103.7 | M14: 104 | N14: 107.4 | O14: 109.9 | P14: 108.1 | Q14: 108.1 | R14: 108.8 | S14: 107.9 | T14: 108.6 | U14: NA | V14: 107.5 | W14: 106.8 | X14: 105.7 | Y14: 104.1 | Z14: 105 | AA14: 105.5 | AB14: 102.1 | AC14: 104.8 | AD14: 107.2
A15: Urban | B15: 2013 | C15: May | D15: 115.4 | E15: 114.2 | F15: 102.7 | G15: 105.5 | H15: 101.5 | I15: 110.6 | J15: 123.7 | K15: 105.2 | L15: 101.9 | M15: 105 | N15: 109.1 | O15: 111.3 | P15: 111.1 | Q15: 109.8 | R15: 108.5 | S15: 106.7 | T15: 108.3 | U15: 100.5 | V15: 107.2 | W15: 107.1 | X15: 106.2 | Y15: 103.9 | Z15: 104.6 | AA15: 105.7 | AB15: 102.6 | AC15: 104.9 | AD15: 106.6
A16: Rural+Urban | B16: 2013 | C16: May | D16: 112.3 | E16: 111.3 | F16: 104.7 | G16: 106.8 | H16: 103.9 | I16: 109.3 | J16: 112.9 | K16: 105.8 | L16: 103.1 | M16: 104.3 | N16: 108.1 | O16: 110.5 | P16: 109.2 | Q16: 108.6 | R16: 108.7 | S16: 107.4 | T16: 108.5 | U16: 100.5 | V16: 107.4 | W16: 106.9 | X16: 105.9 | Y16: 104 | Z16: 104.8 | AA16: 105.6 | AB16: 102.3 | AC16: 104.8 | AD16: 106.9
A17: Rural | B17: 2013 | C17: June | D17: 112.3 | E17: 112.1 | F17: 108.1 | G17: 108.3 | H17: 105.9 | I17: 109.2 | J17: 118 | K17: 106.8 | L17: 104.1 | M17: 105.4 | N17: 108.2 | O17: 111 | P17: 110.6 | Q17: 109 | R17: 109.7 | S17: 108.8 | T17: 109.5 | U17: NA | V17: 108.5 | W17: 107.5 | X17: 106.3 | Y17: 105 | Z17: 105.6 | AA17: 106.5 | AB17: 102.5 | AC17: 105.5 | AD17: 108.9
A18: Urban | B18: 2013 | C18: June | D18: 117 | E18: 120.1 | F18: 112.5 | G18: 107.3 | H18: 101.3 | I18: 112.4 | J18: 143.6 | K18: 105.4 | L18: 101.4 | M18: 106.4 | N18: 110 | O18: 112.2 | P18: 115 | Q18: 110.9 | R18: 109.2 | S18: 107.2 | T18: 108.9 | U18: 106.6 | V18: 108 | W18: 107.7 | X18: 106.5 | Y18: 105.2 | Z18: 105.2 | AA18: 108.1 | AB18: 103.3 | AC18: 106.1 | AD18: 109.7
A19: Rural+Urban | B19: 2013 | C19: June | D19: 113.8 | E19: 114.9 | F19: 109.8 | G19: 107.9 | H19: 104.2 | I19: 110.7 | J19: 126.7 | K19: 106.3 | L19: 103.2 | M19: 105.7 | N19: 109 | O19: 111.6 | P19: 112.2 | Q19: 109.5 | R19: 109.5 | S19: 108.1 | T19: 109.3 | U19: 106.6 | V19: 108.3 | W19: 107.6 | X19: 106.4 | Y19: 105.1 | Z19: 105.4 | AA19: 107.4 | AB19: 102.8 | AC19: 105.8 | AD19: 109.3
A20: Rural | B20: 2013 | C20: July | D20: 113.4 | E20: 114.9 | F20: 110.5 | G20: 109.3 | H20: 106.2 | I20: 110.3 | J20: 129.2 | K20: 107.1 | L20: 104.3 | M20: 106.4 | N20: 109.1 | O20: 112.1 | P20: 113.1 | Q20: 109.8 | R20: 110.5 | S20: 109.5 | T20: 110.3 | U20: NA | V20: 109.5 | W20: 108.3 | X20: 106.9 | Y20: 106.8 | Z20: 106.4 | AA20: 107.8 | AB20: 102.5 | AC20: 106.5 | AD20: 110.7
A21: Urban | B21: 2013 | C21: July | D21: 117.8 | E21: 119.2 | F21: 114 | G21: 108.3 | H21: 101.1 | I21: 113.2 | J21: 160.9 | K21: 105.1 | L21: 101.3 | M21: 107.5 | N21: 110.4 | O21: 113.1 | P21: 117.5 | Q21: 111.7 | R21: 109.8 | S21: 107.8 | T21: 109.5 | U21: 107.7 | V21: 108.6 | W21: 108.1 | X21: 107.1 | Y21: 107.3 | Z21: 105.9 | AA21: 110.1 | AB21: 103.2 | AC21: 107.3 | AD21: 111.4
A22: Rural+Urban | B22: 2013 | C22: July | D22: 114.8 | E22: 116.4 | F22: 111.9 | G22: 108.9 | H22: 104.3 | I22: 111.7 | J22: 140 | K22: 106.4 | L22: 103.3 | M22: 106.8 | N22: 109.6 | O22: 112.6 | P22: 114.7 | Q22: 110.3 | R22: 110.2 | S22: 108.8 | T22: 110 | U22: 107.7 | V22: 109.2 | W22: 108.2 | X22: 107 | Y22: 107.1 | Z22: 106.1 | AA22: 109.1 | AB22: 102.8 | AC22: 106.9 | AD22: 111
A23: Rural | B23: 2013 | C23: August | D23: 114.3 | E23: 115.4 | F23: 111.1 | G23: 110 | H23: 106.4 | I23: 110.8 | J23: 138.9 | K23: 107.4 | L23: 104.1 | M23: 106.9 | N23: 109.7 | O23: 112.6 | P23: 114.9 | Q23: 110.7 | R23: 111.3 | S23: 110.2 | T23: 111.1 | U23: NA | V23: 109.9 | W23: 108.7 | X23: 107.5 | Y23: 107.8 | Z23: 106.8 | AA23: 108.7 | AB23: 105 | AC23: 107.5 | AD23: 112.1
A24: Urban | B24: 2013 | C24: August | D24: 118.3 | E24: 120.4 | F24: 112.7 | G24: 108.9 | H24: 101.1 | I24: 108.7 | J24: 177 | K24: 104.7 | L24: 101 | M24: 108.5 | N24: 110.9 | O24: 114.3 | P24: 119.6 | Q24: 112.4 | R24: 110.6 | S24: 108.3 | T24: 110.2 | U24: 108.9 | V24: 109.3 | W24: 108.7 | X24: 107.6 | Y24: 108.1 | Z24: 106.5 | AA24: 110.8 | AB24: 106 | AC24: 108.3 | AD24: 112.7
A25: Rural+Urban | B25: 2013 | C25: August | D25: 115.6 | E25: 117.2 | F25: 111.7 | G25: 109.6 | H25: 104.5 | I25: 109.8 | J25: 151.8 | K25: 106.5 | L25: 103.1 | M25: 107.4 | N25: 110.2 | O25: 113.4 | P25: 116.6 | Q25: 111.2 | R25: 111 | S25: 109.4 | T25: 110.7 | U25: 108.9 | V25: 109.7 | W25: 108.7 | X25: 107.5 | Y25: 108 | Z25: 106.6 | AA25: 109.9 | AB25: 105.4 | AC25: 107.9 | AD25: 112.4
A26: Rural | B26: 2013 | C26: September | D26: 115.4 | E26: 115.7 | F26: 111.7 | G26: 111 | H26: 107.4 | I26: 110.9 | J26: 154 | K26: 108.1 | L26: 104.2 | M26: 107.9 | N26: 110.4 | O26: 114 | P26: 117.8 | Q26: 111.7 | R26: 112.7 | S26: 111.4 | T26: 112.5 | U26: NA | V26: 111.1 | W26: 109.6 | X26: 108.3 | Y26: 109.3 | Z26: 107.7 | AA26: 109.8 | AB26: 106.7 | AC26: 108.7 | AD26: 114.2
A27: Urban | B27: 2013 | C27: September | D27: 118.6 | E27: 119.1 | F27: 113.2 | G27: 109.6 | H27: 101.7 | I27: 103.2 | J27: 174.3 | K27: 105.1 | L27: 100.8 | M27: 109.1 | N27: 111.1 | O27: 115.4 | P27: 119.2 | Q27: 112.9 | R27: 111.4 | S27: 109 | T27: 111.1 | U27: 109.7 | V27: 109.5 | W27: 109.6 | X27: 107.9 | Y27: 110.4 | Z27: 107.4 | AA27: 111.2 | AB27: 106.9 | AC27: 109.4 | AD27: 113.2
A28: Rural+Urban | B28: 2013 | C28: September | D28: 116.4 | E28: 116.9 | F28: 112.3 | G28: 110.5 | H28: 105.3 | I28: 107.3 | J28: 160.9 | K28: 107.1 | L28: 103.1 | M28: 108.3 | N28: 110.7 | O28: 114.6 | P28: 118.3 | Q28: 112 | R28: 112.2 | S28: 110.4 | T28: 111.9 | U28: 109.7 | V28: 110.5 | W28: 109.6 | X28: 108.1 | Y28: 109.9 | Z28: 107.5 | AA28: 110.6 | AB28: 106.8 | AC28: 109 | AD28: 113.7
A29: Rural | B29: 2013 | C29: October | D29: 116.3 | E29: 115.4 | F29: 112.6 | G29: 111.7 | H29: 107.7 | I29: 113.2 | J29: 164.9 | K29: 108.3 | L29: 103.9 | M29: 108.2 | N29: 111.1 | O29: 114.9 | P29: 119.8 | Q29: 112.2 | R29: 113.6 | S29: 112.3 | T29: 113.4 | U29: NA | V29: 111.6 | W29: 110.4 | X29: 108.9 | Y29: 109.3 | Z29: 108.3 | AA29: 110.2 | AB29: 107.5 | AC29: 109.1 | AD29: 115.5
A30: Urban | B30: 2013 | C30: October | D30: 118.9 | E30: 118.1 | F30: 114.5 | G30: 110.4 | H30: 102.3 | I30: 106.2 | J30: 183.5 | K30: 105.3 | L30: 100.2 | M30: 109.6 | N30: 111.4 | O30: 116 | P30: 120.8 | Q30: 113.5 | R30: 112.5 | S30: 109.7 | T30: 112 | U30: 110.5 | V30: 109.7 | W30: 110.2 | X30: 108.2 | Y30: 109.7 | Z30: 108 | AA30: 111.3 | AB30: 107.3 | AC30: 109.4 | AD30: 114
A31: Rural+Urban | B31: 2013 | C31: October | D31: 117.1 | E31: 116.3 | F31: 113.3 | G31: 111.2 | H31: 105.7 | I31: 109.9 | J31: 171.2 | K31: 107.3 | L31: 102.7 | M31: 108.7 | N31: 111.2 | O31: 115.4 | P31: 120.2 | Q31: 112.5 | R31: 113.2 | S31: 111.2 | T31: 112.8 | U31: 110.5 | V31: 110.9 | W31: 110.3 | X31: 108.6 | Y31: 109.5 | Z31: 108.1 | AA31: 110.8 | AB31: 107.4 | AC31: 109.2 | AD31: 114.8
A32: Rural | B32: 2013 | C32: November | D32: 117.3 | E32: 114.9 | F32: 116.2 | G32: 112.8 | H32: 108.9 | I32: 116.6 | J32: 178.1 | K32: 109.1 | L32: 103.6 | M32: 109 | N32: 111.8 | O32: 116 | P32: 122.5 | Q32: 112.8 | R32: 114.6 | S32: 113.1 | T32: 114.4 | U32: NA | V32: 112.6 | W32: 111.3 | X32: 109.7 | Y32: 109.6 | Z32: 108.7 | AA32: 111 | AB32: 108.2 | AC32: 109.8 | AD32: 117.4
A33: Urban | B33: 2013 | C33: November | D33: 119.8 | E33: 116.3 | F33: 122.6 | G33: 112 | H33: 103.2 | I33: 110 | J33: 192.8 | K33: 106.3 | L33: 99.5 | M33: 110.3 | N33: 111.8 | O33: 117.1 | P33: 122.9 | Q33: 114.1 | R33: 113.5 | S33: 110.3 | T33: 113 | U33: 111.1 | V33: 110 | W33: 110.9 | X33: 108.6 | Y33: 109.5 | Z33: 108.5 | AA33: 111.3 | AB33: 107.9 | AC33: 109.6 | AD33: 115
A34: Rural+Urban | B34: 2013 | C34: November | D34: 118.1 | E34: 115.4 | F34: 118.7 | G34: 112.5 | H34: 106.8 | I34: 113.5 | J34: 183.1 | K34: 108.2 | L34: 102.2 | M34: 109.4 | N34: 111.8 | O34: 116.5 | P34: 122.6 | Q34: 113.1 | R34: 114.2 | S34: 111.9 | T34: 113.8 | U34: 111.1 | V34: 111.6 | W34: 111.1 | X34: 109.3 | Y34: 109.5 | Z34: 108.6 | AA34: 111.2 | AB34: 108.1 | AC34: 109.7 | AD34: 116.3
A35: Rural | B35: 2013 | C35: December | D35: 118.4 | E35: 115.9 | F35: 120.4 | G35: 113.8 | H35: 109.5 | I35: 115.5 | J35: 145.7 | K35: 109.5 | L35: 102.9 | M35: 109.8 | N35: 112.1 | O35: 116.8 | P35: 118.7 | Q35: 113.6 | R35: 115.8 | S35: 114 | T35: 115.5 | U35: NA | V35: 112.8 | W35: 112.1 | X35: 110.1 | Y35: 109.9 | Z35: 109.2 | AA35: 111.6 | AB35: 108.1 | AC35: 110.1 | AD35: 115.5
A36: Urban | B36: 2013 | C36: December | D36: 120.5 | E36: 118.1 | F36: 128.5 | G36: 112.8 | H36: 103.4 | I36: 110.7 | J36: 144.8 | K36: 107.1 | L36: 98.6 | M36: 111.9 | N36: 112.1 | O36: 118.1 | P36: 117.8 | Q36: 115 | R36: 114.2 | S36: 110.9 | T36: 113.7 | U36: 110.7 | V36: 110.4 | W36: 111.3 | X36: 109 | Y36: 109.7 | Z36: 108.9 | AA36: 111.4 | AB36: 107.7 | AC36: 109.8 | AD36: 113.3
A37: Rural+Urban | B37: 2013 | C37: December | D37: 119.1 | E37: 116.7 | F37: 123.5 | G37: 113.4 | H37: 107.3 | I37: 113.3 | J37: 145.4 | K37: 108.7 | L37: 101.5 | M37: 110.5 | N37: 112.1 | O37: 117.4 | P37: 118.4 | Q37: 114 | R37: 115.2 | S37: 112.7 | T37: 114.8 | U37: 110.7 | V37: 111.9 | W37: 111.7 | X37: 109.7 | Y37: 109.8 | Z37: 109 | AA37: 111.5 | AB37: 107.9 | AC37: 110 | AD37: 114.5
A38: Rural | B38: 2014 | C38: January | D38: 118.9 | E38: 117.1 | F38: 120.5 | G38: 114.4 | H38: 109 | I38: 115.5 | J38: 123.9 | K38: 109.6 | L38: 101.8 | M38: 110.2 | N38: 112.4 | O38: 117.3 | P38: 116 | Q38: 114 | R38: 116.5 | S38: 114.5 | T38: 116.2 | U38: NA | V38: 113 | W38: 112.6 | X38: 110.6 | Y38: 110.5 | Z38: 109.6 | AA38: 111.8 | AB38: 108.3 | AC38: 110.6 | AD38: 114.2
A39: Urban | B39: 2014 | C39: January | D39: 121.2 | E39: 122 | F39: 129.9 | G39: 113.6 | H39: 102.9 | I39: 112.1 | J39: 118.9 | K39: 107.5 | L39: 96.9 | M39: 112.7 | N39: 112.1 | O39: 119 | P39: 115.5 | Q39: 115.7 | R39: 114.8 | S39: 111.3 | T39: 114.3 | U39: 111.6 | V39: 111 | W39: 111.9 | X39: 109.7 | Y39: 110.8 | Z39: 109.8 | AA39: 111.5 | AB39: 108 | AC39: 110.5 | AD39: 112.9
A40: Rural+Urban | B40: 2014 | C40: January | D40: 119.6 | E40: 118.8 | F40: 124.1 | G40: 114.1 | H40: 106.8 | I40: 113.9 | J40: 122.2 | K40: 108.9 | L40: 100.2 | M40: 111 | N40: 112.3 | O40: 118.1 | P40: 115.8 | Q40: 114.5 | R40: 115.8 | S40: 113.2 | T40: 115.4 | U40: 111.6 | V40: 112.2 | W40: 112.3 | X40: 110.3 | Y40: 110.7 | Z40: 109.7 | AA40: 111.6 | AB40: 108.2 | AC40: 110.6 | AD40: 113.6
...

Sheet Cleaned Data
A1: Sector | B1: Year | C1: Month | D1: Cereals and products | E1: Meat and fish | F1: Egg | G1: Milk and products | H1: Oils and fats | I1: Fruits | J1: Vegetables | K1: Pulses and products | L1: Sugar and Confectionery | M1: Spices | N1: Non-alcoholic beverages | O1: Prepared meals, snacks, sweets etc. | P1: Food and beverages | Q1: Pan, tobacco and intoxicants | R1: Clothing | S1: Footwear | T1: Clothing and footwear | U1: Housing | V1: Fuel and light | W1: Household goods and services | X1: Health | Y1: Transport and communication | Z1: Recreation and amusement | AA1: Education | AB1: Personal care and effects | AC1: Miscellaneous | AD1: General index
A2: Rural | B2: 2013 | C2: January | D2: 107.5 | E2: 106.3 | F2: 108.1 | G2: 104.9 | H2: 106.1 | I2: 103.9 | J2: 101.9 | K2: 106.1 | L2: 106.8 | M2: 103.1 | N2: 104.8 | O2: 106.7 | P2: 105.5 | Q2: 105.1 | R2: 106.5 | S2: 105.8 | T2: 106.4 | U2: NA | V2: 105.5 | W2: 104.8 | X2: 104 | Y2: 103.3 | Z2: 103.4 | AA2: 103.8 | AB2: 104.7 | AC2: 104 | AD2: 105.1
A3: Urban | B3: 2013 | C3: January | D3: 110.5 | E3: 109.1 | F3: 113 | G3: 103.6 | H3: 103.4 | I3: 102.3 | J3: 102.9 | K3: 105.8 | L3: 105.1 | M3: 101.8 | N3: 105.1 | O3: 107.9 | P3: 105.9 | Q3: 105.2 | R3: 105.9 | S3: 105 | T3: 105.8 | U3: 100.3 | V3: 105.4 | W3: 104.8 | X3: 104.1 | Y3: 103.2 | Z3: 102.9 | AA3: 103.5 | AB3: 104.3 | AC3: 103.7 | AD3: 104
A4: Rural+Urban | B4: 2013 | C4: January | D4: 108.4 | E4: 107.3 | F4: 110 | G4: 104.4 | H4: 105.1 | I4: 103.2 | J4: 102.2 | K4: 106 | L4: 106.2 | M4: 102.7 | N4: 104.9 | O4: 107.3 | P4: 105.6 | Q4: 105.1 | R4: 106.3 | S4: 105.5 | T4: 106.2 | U4: 100.3 | V4: 105.5 | W4: 104.8 | X4: 104 | Y4: 103.2 | Z4: 103.1 | AA4: 103.6 | AB4: 104.5 | AC4: 103.9 | AD4: 104.6
A5: Rural | B5: 2013 | C5: February | D5: 109.2 | E5: 108.7 | F5: 110.2 | G5: 105.4 | H5: 106.7 | I5: 104 | J5: 102.4 | K5: 105.9 | L5: 105.7 | M5: 103.1 | N5: 105.1 | O5: 107.7 | P5: 106.3 | Q5: 105.6 | R5: 107.1 | S5: 106.3 | T5: 107 | U5: NA | V5: 106.2 | W5: 105.2 | X5: 104.4 | Y5: 103.9 | Z5: 104 | AA5: 104.1 | AB5: 104.6 | AC5: 104.4 | AD5: 105.8
A6: Urban | B6: 2013 | C6: February | D6: 112.9 | E6: 112.9 | F6: 116.9 | G6: 104 | H6: 103.5 | I6: 103.1 | J6: 104.9 | K6: 104.1 | L6: 103.8 | M6: 102.3 | N6: 106 | O6: 109 | P6: 107.2 | Q6: 106 | R6: 106.6 | S6: 105.5 | T6: 106.4 | U6: 100.4 | V6: 105.7 | W6: 105.2 | X6: 104.7 | Y6: 104.4 | Z6: 103.3 | AA6: 103.7 | AB6: 104.3 | AC6: 104.3 | AD6: 104.7
A7: Rural+Urban | B7: 2013 | C7: February | D7: 110.4 | E7: 110.2 | F7: 112.8 | G7: 104.9 | H7: 105.5 | I7: 103.6 | J7: 103.2 | K7: 105.3 | L7: 105.1 | M7: 102.8 | N7: 105.5 | O7: 108.3 | P7: 106.6 | Q7: 105.7 | R7: 106.9 | S7: 106 | T7: 106.8 | U7: 100.4 | V7: 106 | W7: 105.2 | X7: 104.5 | Y7: 104.2 | Z7: 103.6 | AA7: 103.9 | AB7: 104.5 | AC7: 104.4 | AD7: 105.3
A8: Rural | B8: 2013 | C8: March | D8: 110.2 | E8: 108.8 | F8: 109.9 | G8: 105.6 | H8: 106.2 | I8: 105.7 | J8: 101.4 | K8: 105.7 | L8: 105 | M8: 103.3 | N8: 105.6 | O8: 108.2 | P8: 106.6 | Q8: 106.5 | R8: 107.6 | S8: 106.8 | T8: 107.5 | U8: NA | V8: 106.1 | W8: 105.6 | X8: 104.7 | Y8: 104.6 | Z8: 104 | AA8: 104.3 | AB8: 104.3 | AC8: 104.6 | AD8: 106
A9: Urban | B9: 2013 | C9: March | D9: 113.9 | E9: 111.4 | F9: 113.2 | G9: 104.3 | H9: 102.7 | I9: 104.9 | J9: 103.8 | K9: 103.5 | L9: 102.6 | M9: 102.4 | N9: 107 | O9: 109.8 | P9: 107.3 | Q9: 106.8 | R9: 107.2 | S9: 106 | T9: 107 | U9: 100.4 | V9: 106 | W9: 105.7 | X9: 105.2 | Y9: 105.5 | Z9: 103.5 | AA9: 103.8 | AB9: 104.2 | AC9: 104.9 | AD9: 105
A10: Rural+Urban | B10: 2013 | C10: March | D10: 111.4 | E10: 109.7 | F10: 111.2 | G10: 105.1 | H10: 104.9 | I10: 105.3 | J10: 102.2 | K10: 105 | L10: 104.2 | M10: 103 | N10: 106.2 | O10: 108.9 | P10: 106.9 | Q10: 106.6 | R10: 107.4 | S10: 106.5 | T10: 107.3 | U10: 100.4 | V10: 106.1 | W10: 105.6 | X10: 104.9 | Y10: 105.1 | Z10: 103.7 | AA10: 104 | AB10: 104.3 | AC10: 104.7 | AD10: 105.5
A11: Rural | B11: 2013 | C11: April | D11: 110.2 | E11: 109.5 | F11: 106.9 | G11: 106.3 | H11: 105.7 | I11: 108.3 | J11: 103.4 | K11: 105.7 | L11: 104.2 | M11: 103.2 | N11: 106.5 | O11: 108.8 | P11: 107.1 | Q11: 107.1 | R11: 108.1 | S11: 107.4 | T11: 108 | U11: NA | V11: 106.5 | W11: 106.1 | X11: 105.1 | Y11: 104.4 | Z11: 104.5 | AA11: 104.8 | AB11: 102.7 | AC11: 104.6 | AD11: 106.4
A12: Urban | B12: 2013 | C12: April | D12: 114.6 | E12: 113.4 | F12: 106 | G12: 104.7 | H12: 102.1 | I12: 109.5 | J12: 109.7 | K12: 104.6 | L12: 102 | M12: 103.5 | N12: 108.2 | O12: 110.6 | P12: 108.8 | Q12: 108.5 | R12: 107.9 | S12: 106.4 | T12: 107.7 | U12: 100.5 | V12: 106.4 | W12: 106.5 | X12: 105.7 | Y12: 105 | Z12: 104 | AA12: 105.2 | AB12: 103.2 | AC12: 105.1 | AD12: 105.7
A13: Rural+Urban | B13: 2013 | C13: April | D13: 111.6 | E13: 110.9 | F13: 106.6 | G13: 105.7 | H13: 104.4 | I13: 108.9 | J13: 105.5 | K13: 105.3 | L13: 103.5 | M13: 103.3 | N13: 107.2 | O13: 109.6 | P13: 107.7 | Q13: 107.5 | R13: 108 | S13: 107 | T13: 107.9 | U13: 100.5 | V13: 106.5 | W13: 106.3 | X13: 105.3 | Y13: 104.7 | Z13: 104.2 | AA13: 105 | AB13: 102.9 | AC13: 104.8 | AD13: 106.1
A14: Rural | B14: 2013 | C14: May | D14: 110.9 | E14: 109.8 | F14: 105.9 | G14: 107.5 | H14: 105.3 | I14: 108.1 | J14: 107.3 | K14: 106.1 | L14: 103.7 | M14: 104 | N14: 107.4 | O14: 109.9 | P14: 108.1 | Q14: 108.1 | R14: 108.8 | S14: 107.9 | T14: 108.6 | U14: NA | V14: 107.5 | W14: 106.8 | X14: 105.7 | Y14: 104.1 | Z14: 105 | AA14: 105.5 | AB14: 102.1 | AC14: 104.8 | AD14: 107.2
A15: Urban | B15: 2013 | C15: May | D15: 115.4 | E15: 114.2 | F15: 102.7 | G15: 105.5 | H15: 101.5 | I15: 110.6 | J15: 123.7 | K15: 105.2 | L15: 101.9 | M15: 105 | N15: 109.1 | O15: 111.3 | P15: 111.1 | Q15: 109.8 | R15: 108.5 | S15: 106.7 | T15: 108.3 | U15: 100.5 | V15: 107.2 | W15: 107.1 | X15: 106.2 | Y15: 103.9 | Z15: 104.6 | AA15: 105.7 | AB15: 102.6 | AC15: 104.9 | AD15: 106.6
A16: Rural+Urban | B16: 2013 | C16: May | D16: 112.3 | E16: 111.3 | F16: 104.7 | G16: 106.8 | H16: 103.9 | I16: 109.3 | J16: 112.9 | K16: 105.8 | L16: 103.1 | M16: 104.3 | N16: 108.1 | O16: 110.5 | P16: 109.2 | Q16: 108.6 | R16: 108.7 | S16: 107.4 | T16: 108.5 | U16: 100.5 | V16: 107.4 | W16: 106.9 | X16: 105.9 | Y16: 104 | Z16: 104.8 | AA16: 105.6 | AB16: 102.3 | AC16: 104.8 | AD16: 106.9
A17: Rural | B17: 2013 | C17: June | D17: 112.3 | E17: 112.1 | F17: 108.1 | G17: 108.3 | H17: 105.9 | I17: 109.2 | J17: 118 | K17: 106.8 | L17: 104.1 | M17: 105.4 | N17: 108.2 | O17: 111 | P17: 110.6 | Q17: 109 | R17: 109.7 | S17: 108.8 | T17: 109.5 | U17: NA | V17: 108.5 | W17: 107.5 | X17: 106.3 | Y17: 105 | Z17: 105.6 | AA17: 106.5 | AB17: 102.5 | AC17: 105.5 | AD17: 108.9
A18: Urban | B18: 2013 | C18: June | D18: 117 | E18: 120.1 | F18: 112.5 | G18: 107.3 | H18: 101.3 | I18: 112.4 | J18: 143.6 | K18: 105.4 | L18: 101.4 | M18: 106.4 | N18: 110 | O18: 112.2 | P18: 115 | Q18: 110.9 | R18: 109.2 | S18: 107.2 | T18: 108.9 | U18: 106.6 | V18: 108 | W18: 107.7 | X18: 106.5 | Y18: 105.2 | Z18: 105.2 | AA18: 108.1 | AB18: 103.3 | AC18: 106.1 | AD18: 109.7
A19: Rural+Urban | B19: 2013 | C19: June | D19: 113.8 | E19: 114.9 | F19: 109.8 | G19: 107.9 | H19: 104.2 | I19: 110.7 | J19: 126.7 | K19: 106.3 | L19: 103.2 | M19: 105.7 | N19: 109 | O19: 111.6 | P19: 112.2 | Q19: 109.5 | R19: 109.5 | S19: 108.1 | T19: 109.3 | U19: 106.6 | V19: 108.3 | W19: 107.6 | X19: 106.4 | Y19: 105.1 | Z19: 105.4 | AA19: 107.4 | AB19: 102.8 | AC19: 105.8 | AD19: 109.3
A20: Rural | B20: 2013 | C20: July | D20: 113.4 | E20: 114.9 | F20: 110.5 | G20: 109.3 | H20: 106.2 | I20: 110.3 | J20: 129.2 | K20: 107.1 | L20: 104.3 | M20: 106.4 | N20: 109.1 | O20: 112.1 | P20: 113.1 | Q20: 109.8 | R20: 110.5 | S20: 109.5 | T20: 110.3 | U20: NA | V20: 109.5 | W20: 108.3 | X20: 106.9 | Y20: 106.8 | Z20: 106.4 | AA20: 107.8 | AB20: 102.5 | AC20: 106.5 | AD20: 110.7
A21: Urban | B21: 2013 | C21: July | D21: 117.8 | E21: 119.2 | F21: 114 | G21: 108.3 | H21: 101.1 | I21: 113.2 | J21: 160.9 | K21: 105.1 | L21: 101.3 | M21: 107.5 | N21: 110.4 | O21: 113.1 | P21: 117.5 | Q21: 111.7 | R21: 109.8 | S21: 107.8 | T21: 109.5 | U21: 107.7 | V21: 108.6 | W21: 108.1 | X21: 107.1 | Y21: 107.3 | Z21: 105.9 | AA21: 110.1 | AB21: 103.2 | AC21: 107.3 | AD21: 111.4
A22: Rural+Urban | B22: 2013 | C22: July | D22: 114.8 | E22: 116.4 | F22: 111.9 | G22: 108.9 | H22: 104.3 | I22: 111.7 | J22: 140 | K22: 106.4 | L22: 103.3 | M22: 106.8 | N22: 109.6 | O22: 112.6 | P22: 114.7 | Q22: 110.3 | R22: 110.2 | S22: 108.8 | T22: 110 | U22: 107.7 | V22: 109.2 | W22: 108.2 | X22: 107 | Y22: 107.1 | Z22: 106.1 | AA22: 109.1 | AB22: 102.8 | AC22: 106.9 | AD22: 111
A23: Rural | B23: 2013 | C23: August | D23: 114.3 | E23: 115.4 | F23: 111.1 | G23: 110 | H23: 106.4 | I23: 110.8 | J23: 138.9 | K23: 107.4 | L23: 104.1 | M23: 106.9 | N23: 109.7 | O23: 112.6 | P23: 114.9 | Q23: 110.7 | R23: 111.3 | S23: 110.2 | T23: 111.1 | U23: NA | V23: 109.9 | W23: 108.7 | X23: 107.5 | Y23: 107.8 | Z23: 106.8 | AA23: 108.7 | AB23: 105 | AC23: 107.5 | AD23: 112.1
A24: Urban | B24: 2013 | C24: August | D24: 118.3 | E24: 120.4 | F24: 112.7 | G24: 108.9 | H24: 101.1 | I24: 108.7 | J24: 177 | K24: 104.7 | L24: 101 | M24: 108.5 | N24: 110.9 | O24: 114.3 | P24: 119.6 | Q24: 112.4 | R24: 110.6 | S24: 108.3 | T24: 110.2 | U24: 108.9 | V24: 109.3 | W24: 108.7 | X24: 107.6 | Y24: 108.1 | Z24: 106.5 | AA24: 110.8 | AB24: 106 | AC24: 108.3 | AD24: 112.7
A25: Rural+Urban | B25: 2013 | C25: August | D25: 115.6 | E25: 117.2 | F25: 111.7 | G25: 109.6 | H25: 104.5 | I25: 109.8 | J25: 151.8 | K25: 106.5 | L25: 103.1 | M25: 107.4 | N25: 110.2 | O25: 113.4 | P25: 116.6 | Q25: 111.2 | R25: 111 | S25: 109.4 | T25: 110.7 | U25: 108.9 | V25: 109.7 | W25: 108.7 | X25: 107.5 | Y25: 108 | Z25: 106.6 | AA25: 109.9 | AB25: 105.4 | AC25: 107.9 | AD25: 112.4
A26: Rural | B26: 2013 | C26: September | D26: 115.4 | E26: 115.7 | F26: 111.7 | G26: 111 | H26: 107.4 | I26: 110.9 | J26: 154 | K26: 108.1 | L26: 104.2 | M26: 107.9 | N26: 110.4 | O26: 114 | P26: 117.8 | Q26: 111.7 | R26: 112.7 | S26: 111.4 | T26: 112.5 | U26: NA | V26: 111.1 | W26: 109.6 | X26: 108.3 | Y26: 109.3 | Z26: 107.7 | AA26: 109.8 | AB26: 106.7 | AC26: 108.7 | AD26: 114.2
A27: Urban | B27: 2013 | C27: September | D27: 118.6 | E27: 119.1 | F27: 113.2 | G27: 109.6 | H27: 101.7 | I27: 103.2 | J27: 174.3 | K27: 105.1 | L27: 100.8 | M27: 109.1 | N27: 111.1 | O27: 115.4 | P27: 119.2 | Q27: 112.9 | R27: 111.4 | S27: 109 | T27: 111.1 | U27: 109.7 | V27: 109.5 | W27: 109.6 | X27: 107.9 | Y27: 110.4 | Z27: 107.4 | AA27: 111.2 | AB27: 106.9 | AC27: 109.4 | AD27: 113.2
A28: Rural+Urban | B28: 2013 | C28: September | D28: 116.4 | E28: 116.9 | F28: 112.3 | G28: 110.5 | H28: 105.3 | I28: 107.3 | J28: 160.9 | K28: 107.1 | L28: 103.1 | M28: 108.3 | N28: 110.7 | O28: 114.6 | P28: 118.3 | Q28: 112 | R28: 112.2 | S28: 110.4 | T28: 111.9 | U28: 109.7 | V28: 110.5 | W28: 109.6 | X28: 108.1 | Y28: 109.9 | Z28: 107.5 | AA28: 110.6 | AB28: 106.8 | AC28: 109 | AD28: 113.7
A29: Rural | B29: 2013 | C29: October | D29: 116.3 | E29: 115.4 | F29: 112.6 | G29: 111.7 | H29: 107.7 | I29: 113.2 | J29: 164.9 | K29: 108.3 | L29: 103.9 | M29: 108.2 | N29: 111.1 | O29: 114.9 | P29: 119.8 | Q29: 112.2 | R29: 113.6 | S29: 112.3 | T29: 113.4 | U29: NA | V29: 111.6 | W29: 110.4 | X29: 108.9 | Y29: 109.3 | Z29: 108.3 | AA29: 110.2 | AB29: 107.5 | AC29: 109.1 | AD29: 115.5
A30: Urban | B30: 2013 | C30: October | D30: 118.9 | E30: 118.1 | F30: 114.5 | G30: 110.4 | H30: 102.3 | I30: 106.2 | J30: 183.5 | K30: 105.3 | L30: 100.2 | M30: 109.6 | N30: 111.4 | O30: 116 | P30: 120.8 | Q30: 113.5 | R30: 112.5 | S30: 109.7 | T30: 112 | U30: 110.5 | V30: 109.7 | W30: 110.2 | X30: 108.2 | Y30: 109.7 | Z30: 108 | AA30: 111.3 | AB30: 107.3 | AC30: 109.4 | AD30: 114
A31: Rural+Urban | B31: 2013 | C31: October | D31: 117.1 | E31: 116.3 | F31: 113.3 | G31: 111.2 | H31: 105.7 | I31: 109.9 | J31: 171.2 | K31: 107.3 | L31: 102.7 | M31: 108.7 | N31: 111.2 | O31: 115.4 | P31: 120.2 | Q31: 112.5 | R31: 113.2 | S31: 111.2 | T31: 112.8 | U31: 110.5 | V31: 110.9 | W31: 110.3 | X31: 108.6 | Y31: 109.5 | Z31: 108.1 | AA31: 110.8 | AB31: 107.4 | AC31: 109.2 | AD31: 114.8
A32: Rural | B32: 2013 | C32: November | D32: 117.3 | E32: 114.9 | F32: 116.2 | G32: 112.8 | H32: 108.9 | I32: 116.6 | J32: 178.1 | K32: 109.1 | L32: 103.6 | M32: 109 | N32: 111.8 | O32: 116 | P32: 122.5 | Q32: 112.8 | R32: 114.6 | S32: 113.1 | T32: 114.4 | U32: NA | V32: 112.6 | W32: 111.3 | X32: 109.7 | Y32: 109.6 | Z32: 108.7 | AA32: 111 | AB32: 108.2 | AC32: 109.8 | AD32: 117.4
A33: Urban | B33: 2013 | C33: November | D33: 119.8 | E33: 116.3 | F33: 122.6 | G33: 112 | H33: 103.2 | I33: 110 | J33: 192.8 | K33: 106.3 | L33: 99.5 | M33: 110.3 | N33: 111.8 | O33: 117.1 | P33: 122.9 | Q33: 114.1 | R33: 113.5 | S33: 110.3 | T33: 113 | U33: 111.1 | V33: 110 | W33: 110.9 | X33: 108.6 | Y33: 109.5 | Z33: 108.5 | AA33: 111.3 | AB33: 107.9 | AC33: 109.6 | AD33: 115
A34: Rural+Urban | B34: 2013 | C34: November | D34: 118.1 | E34: 115.4 | F34: 118.7 | G34: 112.5 | H34: 106.8 | I34: 113.5 | J34: 183.1 | K34: 108.2 | L34: 102.2 | M34: 109.4 | N34: 111.8 | O34: 116.5 | P34: 122.6 | Q34: 113.1 | R34: 114.2 | S34: 111.9 | T34: 113.8 | U34: 111.1 | V34: 111.6 | W34: 111.1 | X34: 109.3 | Y34: 109.5 | Z34: 108.6 | AA34: 111.2 | AB34: 108.1 | AC34: 109.7 | AD34: 116.3
A35: Rural | B35: 2013 | C35: December | D35: 118.4 | E35: 115.9 | F35: 120.4 | G35: 113.8 | H35: 109.5 | I35: 115.5 | J35: 145.7 | K35: 109.5 | L35: 102.9 | M35: 109.8 | N35: 112.1 | O35: 116.8 | P35: 118.7 | Q35: 113.6 | R35: 115.8 | S35: 114 | T35: 115.5 | U35: NA | V35: 112.8 | W35: 112.1 | X35: 110.1 | Y35: 109.9 | Z35: 109.2 | AA35: 111.6 | AB35: 108.1 | AC35: 110.1 | AD35: 115.5
A36: Urban | B36: 2013 | C36: December | D36: 120.5 | E36: 118.1 | F36: 128.5 | G36: 112.8 | H36: 103.4 | I36: 110.7 | J36: 144.8 | K36: 107.1 | L36: 98.6 | M36: 111.9 | N36: 112.1 | O36: 118.1 | P36: 117.8 | Q36: 115 | R36: 114.2 | S36: 110.9 | T36: 113.7 | U36: 110.7 | V36: 110.4 | W36: 111.3 | X36: 109 | Y36: 109.7 | Z36: 108.9 | AA36: 111.4 | AB36: 107.7 | AC36: 109.8 | AD36: 113.3
A37: Rural+Urban | B37: 2013 | C37: December | D37: 119.1 | E37: 116.7 | F37: 123.5 | G37: 113.4 | H37: 107.3 | I37: 113.3 | J37: 145.4 | K37: 108.7 | L37: 101.5 | M37: 110.5 | N37: 112.1 | O37: 117.4 | P37: 118.4 | Q37: 114 | R37: 115.2 | S37: 112.7 | T37: 114.8 | U37: 110.7 | V37: 111.9 | W37: 111.7 | X37: 109.7 | Y37: 109.8 | Z37: 109 | AA37: 111.5 | AB37: 107.9 | AC37: 110 | AD37: 114.5
A38: Rural | B38: 2014 | C38: January | D38: 118.9 | E38: 117.1 | F38: 120.5 | G38: 114.4 | H38: 109 | I38: 115.5 | J38: 123.9 | K38: 109.6 | L38: 101.8 | M38: 110.2 | N38: 112.4 | O38: 117.3 | P38: 116 | Q38: 114 | R38: 116.5 | S38: 114.5 | T38: 116.2 | U38: NA | V38: 113 | W38: 112.6 | X38: 110.6 | Y38: 110.5 | Z38: 109.6 | AA38: 111.8 | AB38: 108.3 | AC38: 110.6 | AD38: 114.2
A39: Urban | B39: 2014 | C39: January | D39: 121.2 | E39: 122 | F39: 129.9 | G39: 113.6 | H39: 102.9 | I39: 112.1 | J39: 118.9 | K39: 107.5 | L39: 96.9 | M39: 112.7 | N39: 112.1 | O39: 119 | P39: 115.5 | Q39: 115.7 | R39: 114.8 | S39: 111.3 | T39: 114.3 | U39: 111.6 | V39: 111 | W39: 111.9 | X39: 109.7 | Y39: 110.8 | Z39: 109.8 | AA39: 111.5 | AB39: 108 | AC39: 110.5 | AD39: 112.9
A40: Rural+Urban | B40: 2014 | C40: January | D40: 119.6 | E40: 118.8 | F40: 124.1 | G40: 114.1 | H40: 106.8 | I40: 113.9 | J40: 122.2 | K40: 108.9 | L40: 100.2 | M40: 111 | N40: 112.3 | O40: 118.1 | P40: 115.8 | Q40: 114.5 | R40: 115.8 | S40: 113.2 | T40: 115.4 | U40: 111.6 | V40: 112.2 | W40: 112.3 | X40: 110.3 | Y40: 110.7 | Z40: 109.7 | AA40: 111.6 | AB40: 108.2 | AC40: 110.6 | AD40: 113.6
...

Sheet PS1
A1: MONTH : MAY 2023 | F1: 3 | G1: <<<<< SELECT SECTOR
F3: Buckets | G3: =INDEX(A31:A33, SECTOR) -> Rural+Urban
A4: Sector | B4: Rural | C4: Urban | D4: Rural+Urban | F4: Food and Beverages | G4: =SUMIF($F$12:$F$34, F4, $H$12:$H$34) -> 0.51728497
A5: Cereals and products | B5: 173.2 | C5: 174.7 | D5: 173.7 | F5: Pan, tobacco and intoxicants | G5: =SUMIF($F$12:$F$34, F5, $H$12:$H$34) -> 0.048864686
A6: Meat and fish | B6: 211.5 | C6: 219.4 | D6: 214.3 | F6: Clothing and footwear | G6: =SUMIF($F$12:$F$34, F6, $H$12:$H$34) -> 0.089220596
A7: Egg | B7: 171 | C7: 176.7 | D7: 173.2 | F7: Housing | G7: =SUMIF($F$12:$F$34, F7, $H$12:$H$34) -> 0.042689746
A8: Milk and products | B8: 179.6 | C8: 179.4 | D8: 179.5 | F8: Fuel and light | G8: =SUMIF($F$12:$F$34, F8, $H$12:$H$34) -> 0.044440123
A9: Oils and fats | B9: 173.3 | C9: 164.4 | D9: 170 | F9: Miscellaneous | G9: =SUMIF($F$12:$F$34, F9, $H$12:$H$34) -> 0.25749988
A10: Fruits | B10: 169 | C10: 175.8 | D10: 172.2
A11: Vegetables | B11: 148.7 | C11: 185 | D11: 161 | F11: Buckets | G11: Categories | H11: =INDEX(A31:A33, SECTOR) -> Rural+Urban
A12: Pulses and products | B12: 174.9 | C12: 176.9 | D12: 175.6 | F12: Food and Beverages | G12: Cereals and products | H12: =IF($H$11="Rural", IFERROR(VALUE(B5),0)/B$28, IF($H$11="Urban", IFERROR(VALUE(C5),0)/C$28, IFERROR(VALUE(D5),0)/D$28)) -> 0.042227841
A13: Sugar and Confectionery | B13: 121.9 | C13: 124.2 | D13: 122.7 | F13: Food and Beverages | G13: Meat and fish | H13: =IF($H$11="Rural", IFERROR(VALUE(B6),0)/B$28, IF($H$11="Urban", IFERROR(VALUE(C6),0)/C$28, IFERROR(VALUE(D6),0)/D$28)) -> 0.052098021
A14: Spices | B14: 221 | C14: 211.9 | D14: 218 | F14: Food and Beverages | G14: Egg | H14: =IF($H$11="Rural", IFERROR(VALUE(B7),0)/B$28, IF($H$11="Urban", IFERROR(VALUE(C7),0)/C$28, IFERROR(VALUE(D7),0)/D$28)) -> 0.042106287
A15: Non-alcoholic beverages | B15: 178.7 | C15: 165.9 | D15: 173.4 | F15: Food and Beverages | G15: Milk and products | H15: =IF($H$11="Rural", IFERROR(VALUE(B8),0)/B$28, IF($H$11="Urban", IFERROR(VALUE(C8),0)/C$28, IFERROR(VALUE(D8),0)/D$28)) -> 0.043637866
A16: Prepared meals, snacks, sweets etc. | B16: 191.1 | C16: 197.7 | D16: 194.2 | F16: Food and Beverages | G16: Oils and fats | H16: =IF($H$11="Rural", IFERROR(VALUE(B9),0)/B$28, IF($H$11="Urban", IFERROR(VALUE(C9),0)/C$28, IFERROR(VALUE(D9),0)/D$28)) -> 0.041328342
A17: Pan, tobacco and intoxicants | B17: 199.9 | C17: 204.2 | D17: 201 | F17: Food and Beverages | G17: Fruits | H17: =IF($H$11="Rural", IFERROR(VALUE(B10),0)/B$28, IF($H$11="Urban", IFERROR(VALUE(C10),0)/C$28, IFERROR(VALUE(D10),0)/D$28)) -> 0.041863179
A18: Clothing | B18: 191.2 | C18: 181.3 | D18: 187.3 | F18: Food and Beverages | G18: Vegetables | H18: =IF($H$11="Rural", IFERROR(VALUE(B11),0)/B$28, IF($H$11="Urban", IFERROR(VALUE(C11),0)/C$28, IFERROR(VALUE(D11),0)/D$28)) -> 0.03914037
A19: Footwear | B19: 187.9 | C19: 168.1 | D19: 179.7 | F19: Food and Beverages | G19: Pulses and products | H19: =IF($H$11="Rural", IFERROR(VALUE(B12),0)/B$28, IF($H$11="Urban", IFERROR(VALUE(C12),0)/C$28, IFERROR(VALUE(D12),0)/D$28)) -> 0.042689746
A20: Housing | B20: NA | C20: 175.6 | D20: 175.6 | F20: Food and Beverages | G20: Sugar and Confectionery | H20: =IF($H$11="Rural", IFERROR(VALUE(B13),0)/B$28, IF($H$11="Urban", IFERROR(VALUE(C13),0)/C$28, IFERROR(VALUE(D13),0)/D$28)) -> 0.029829338
A21: Fuel and light | B21: 182.5 | C21: 183.4 | D21: 182.8 | F21: Food and Beverages | G21: Spices | H21: =IF($H$11="Rural", IFERROR(VALUE(B14),0)/B$28, IF($H$11="Urban", IFERROR(VALUE(C14),0)/C$28, IFERROR(VALUE(D14),0)/D$28)) -> 0.05299752
A22: Household goods and services | B22: 179.8 | C22: 170.1 | D22: 175.2 | F22: Food and Beverages | G22: Non-alcoholic beverages | H22: =IF($H$11="Rural", IFERROR(VALUE(B15),0)/B$28, IF($H$11="Urban", IFERROR(VALUE(C15),0)/C$28, IFERROR(VALUE(D15),0)/D$28)) -> 0.042154908
A23: Health | B23: 187.8 | C23: 182.2 | D23: 185.7 | F23: Food and Beverages | G23: Prepared meals, snacks, sweets etc. | H23: =IF($H$11="Rural", IFERROR(VALUE(B16),0)/B$28, IF($H$11="Urban", IFERROR(VALUE(C16),0)/C$28, IFERROR(VALUE(D16),0)/D$28)) -> 0.047211552
A24: Transport and communication | B24: 169.7 | C24: 160.4 | D24: 164.8 | F24: Pan, tobacco and intoxicants | G24: Pan, tobacco and intoxicants | H24: =IF($H$11="Rural", IFERROR(VALUE(B17),0)/B$28, IF($H$11="Urban", IFERROR(VALUE(C17),0)/C$28, IFERROR(VALUE(D17),0)/D$28)) -> 0.048864686
A25: Recreation and amusement | B25: 173.8 | C25: 169.2 | D25: 171.2 | F25: Clothing and footwear | G25: Clothing | H25: =IF($H$11="Rural", IFERROR(VALUE(B18),0)/B$28, IF($H$11="Urban", IFERROR(VALUE(C18),0)/C$28, IFERROR(VALUE(D18),0)/D$28)) -> 0.045534108
A26: Education | B26: 180.3 | C26: 174.8 | D26: 177.1 | F26: Clothing and footwear | G26: Footwear | H26: =IF($H$11="Rural", IFERROR(VALUE(B19),0)/B$28, IF($H$11="Urban", IFERROR(VALUE(C19),0)/C$28, IFERROR(VALUE(D19),0)/D$28)) -> 0.043686488
A27: Personal care and effects | B27: 184.9 | C27: 185.6 | D27: 185.2 | F27: Housing | G27: Housing | H27: =IF($H$11="Rural", IFERROR(VALUE(B20),0)/B$28, IF($H$11="Urban", IFERROR(VALUE(C20),0)/C$28, IFERROR(VALUE(D20),0)/D$28)) -> 0.042689746
B28: =SUM(Table2[Rural]) -> 3951.7 | C28: =SUM(Table2[Urban]) -> 4106.9 | D28: =SUM(Table2[Rural+Urban]) -> 4113.4 | F28: Fuel and light | G28: Fuel and light | H28: =IF($H$11="Rural", IFERROR(VALUE(B21),0)/B$28, IF($H$11="Urban", IFERROR(VALUE(C21),0)/C$28, IFERROR(VALUE(D21),0)/D$28)) -> 0.044440123
F29: Miscellaneous | G29: Household goods and services | H29: =IF($H$11="Rural", IFERROR(VALUE(B22),0)/B$28, IF($H$11="Urban", IFERROR(VALUE(C22),0)/C$28, IFERROR(VALUE(D22),0)/D$28)) -> 0.042592503
F30: Miscellaneous | G30: Health | H30: =IF($H$11="Rural", IFERROR(VALUE(B23),0)/B$28, IF($H$11="Urban", IFERROR(VALUE(C23),0)/C$28, IFERROR(VALUE(D23),0)/D$28)) -> 0.045145135
A31: Rural | F31: Miscellaneous | G31: Transport and communication | H31: =IF($H$11="Rural", IFERROR(VALUE(B24),0)/B$28, IF($H$11="Urban", IFERROR(VALUE(C24),0)/C$28, IFERROR(VALUE(D24),0)/D$28)) -> 0.04006418
A32: Urban | F32: Miscellaneous | G32: Recreation and amusement | H32: =IF($H$11="Rural", IFERROR(VALUE(B25),0)/B$28, IF($H$11="Urban", IFERROR(VALUE(C25),0)/C$28, IFERROR(VALUE(D25),0)/D$28)) -> 0.041620071
A33: Rural+Urban | F33: Miscellaneous | G33: Education | H33: =IF($H$11="Rural", IFERROR(VALUE(B26),0)/B$28, IF($H$11="Urban", IFERROR(VALUE(C26),0)/C$28, IFERROR(VALUE(D26),0)/D$28)) -> 0.043054408
F34: Miscellaneous | G34: Personal care and effects | H34: =IF($H$11="Rural", IFERROR(VALUE(B27),0)/B$28, IF($H$11="Urban", IFERROR(VALUE(C27),0)/C$28, IFERROR(VALUE(D27),0)/D$28)) -> 0.045023581

Sheet PS2
L1: 2022 had the highest year-on-year CPI inflation for the Rural+Urban sector in May at 7.04%. The reasons could be:
A2: sector: RURAL+URBAN
A4: Year | B4: General Index | C4: Growth | D4: Highest
A5: 2016 | B5: 128.6 | C5: - | D5: =IF(C5=MAX(C$6:C$12), C5, NA()) -> #N/A
A6: 2017 | B6: 131.4 | C6: =B6/B5-1 -> 0.021772939 | D6: =IF(C6=MAX(C$6:C$12), C6, NA()) -> #N/A
A7: 2018 | B7: 137.8 | C7: =B7/B6-1 -> 0.04870624 | D7: =IF(C7=MAX(C$6:C$12), C7, NA()) -> #N/A
A8: 2019 | B8: 142 | C8: =B8/B7-1 -> 0.030478955 | D8: =IF(C8=MAX(C$6:C$12), C8, NA()) -> #N/A
A9: 2020 | B9: 151.8 | C9: =B9/B8-1 -> 0.069014085 | D9: =IF(C9=MAX(C$6:C$12), C9, NA()) -> #N/A
A10: 2021 | B10: 160.4 | C10: =B10/B9-1 -> 0.056653491 | D10: =IF(C10=MAX(C$6:C$12), C10, NA()) -> #N/A
A11: 2022 | B11: 171.7 | C11: =B11/B10-1 -> 0.070448878 | D11: =IF(C11=MAX(C$6:C$12), C11, NA()) -> 0.070448878
A12: 2023 | B12: 179.1 | C12: =B12/B11-1 -> 0.043098427 | D12: =IF(C12=MAX(C$6:C$12), C12, NA()) -> #N/A

Sheet PS3
A1: Month | B1: Rural | C1: Urban | D1: Rural+Urban
A2: 44713 | B2: ='Cleaned Data'!P338 -> 172.4 | C2: ='Cleaned Data'!P339 -> 179.3 | D2: ='Cleaned Data'!P340 -> 174.9
A3: 44743 | B3: ='Cleaned Data'!P341 -> 172.5 | C3: ='Cleaned Data'!P342 -> 179.4 | D3: ='Cleaned Data'!P343 -> 175
A4: 44774 | B4: ='Cleaned Data'!P344 -> 173.9 | C4: ='Cleaned Data'!P345 -> 180.4 | D4: ='Cleaned Data'!P346 -> 176.3
A5: 44805 | B5: ='Cleaned Data'!P347 -> 175.5 | C5: ='Cleaned Data'!P348 -> 181.8 | D5: ='Cleaned Data'!P349 -> 177.8
A6: 44835 | B6: ='Cleaned Data'!P350 -> 177.4 | C6: ='Cleaned Data'!P351 -> 183.3 | D6: ='Cleaned Data'!P352 -> 179.6
A7: 44866 | B7: ='Cleaned Data'!P353 -> 176.6 | C7: ='Cleaned Data'!P354 -> 181.3 | D7: ='Cleaned Data'!P355 -> 178.3
A8: 44896 | B8: ='Cleaned Data'!P356 -> 174.4 | C8: ='Cleaned Data'!P357 -> 178.6 | D8: ='Cleaned Data'!P358 -> 175.9
A9: 44927 | B9: ='Cleaned Data'!P359 -> 175 | C9: ='Cleaned Data'!P360 -> 179.5 | D9: ='Cleaned Data'!P361 -> 176.7
A10: 44958 | B10: ='Cleaned Data'!P362 -> 174.8 | C10: ='Cleaned Data'!P363 -> 180.7 | D10: ='Cleaned Data'!P364 -> 177
A11: 44986 | B11: ='Cleaned Data'!P365 -> 174.8 | C11: ='Cleaned Data'!P366 -> 180.8 | D11: ='Cleaned Data'!P367 -> 177
A12: 45017 | B12: ='Cleaned Data'!P368 -> 175.5 | C12: ='Cleaned Data'!P369 -> 182.1 | D12: ='Cleaned Data'!P370 -> 177.9
A13: 45047 | B13: ='Cleaned Data'!P371 -> 176.8 | C13: ='Cleaned Data'!P372 -> 183.1 | D13: ='Cleaned Data'!P373 -> 179.1
A15: Monthly Inflation Rate
A16: Month | B16: Rural | C16: Urban | D16: Rural+Urban
A17: 44713 | B17: =(B2/'Cleaned Data'!P335) -1 -> 0.0093676815 | C17: =(C2/'Cleaned Data'!P336) -1 -> 0.010140845 | D17: =(D2/'Cleaned Data'!P337) -1 -> 0.0092325447
A18: 44743 | B18: =B3/B2 -1 -> 0.0005800464 | C18: =C3/C2 -1 -> 0.00055772448 | D18: =D3/D2 -1 -> 0.00057175529
A19: 44774 | B19: =B4/B3 -1 -> 0.008115942 | C19: =C4/C3 -1 -> 0.005574136 | D19: =D4/D3 -1 -> 0.0074285714
A20: 44805 | B20: =B5/B4 -1 -> 0.0092006901 | C20: =C5/C4 -1 -> 0.0077605322 | D20: =D5/D4 -1 -> 0.0085082246
A21: 44835 | B21: =B6/B5 -1 -> 0.010826211 | C21: =C6/C5 -1 -> 0.0082508251 | D21: =D6/D5 -1 -> 0.010123735
A22: 44866 | B22: =B7/B6 -1 -> -0.0045095829 | C22: =C7/C6 -1 -> -0.010911075 | D22: =D7/D6 -1 -> -0.0072383073
A23: 44896 | B23: =B8/B7 -1 -> -0.012457531 | C23: =C8/C7 -1 -> -0.014892443 | D23: =D8/D7 -1 -> -0.01346046
A24: 44927 | B24: =B9/B8 -1 -> 0.003440367 | C24: =C9/C8 -1 -> 0.0050391937 | D24: =D9/D8 -1 -> 0.0045480387
A25: 44958 | B25: =B10/B9 -1 -> -0.0011428571 | C25: =C10/C9 -1 -> 0.0066852368 | D25: =D10/D9 -1 -> 0.0016977929
A26: 44986 | B26: =B11/B10 -1 -> 0 | C26: =C11/C10 -1 -> 0.00055340343 | D26: =D11/D10 -1 -> 0
A27: 45017 | B27: =B12/B11 -1 -> 0.0040045767 | C27: =C12/C11 -1 -> 0.0071902655 | D27: =D12/D11 -1 -> 0.0050847458
A28: 45047 | B28: =B13/B12 -1 -> 0.0074074074 | C28: =C13/C12 -1 -> 0.0054914882 | D28: =D13/D12 -1 -> 0.0067453626
B33: Rural | E33: Urban | H33: Rural+Urban
A34: Categories | B34: 44713 | C34: 45047 | D34: Change | E34: 44713 | F34: 45047 | G34: Change | H34: 44713 | I34: 45047 | J34: Change
A35: Cereals and products | B35: 153.8 | C35: 173.2 | D35: =C35-B35 -> 19.4 | E35: 157.5 | F35: 174.7 | G35: =F35-E35 -> 17.2 | H35: 155 | I35: 173.7 | J35: =I35-H35 -> 18.7
A36: Meat and fish | B36: 217.2 | C36: 211.5 | D36: =C36-B36 -> -5.7 | E36: 223.4 | F36: 219.4 | G36: =F36-E36 -> -4 | H36: 219.4 | I36: 214.3 | J36: =I36-H36 -> -5.1
A37: Egg | B37: 169.6 | C37: 171 | D37: =C37-B37 -> 1.4 | E37: 172.8 | F37: 176.7 | G37: =F37-E37 -> 3.9 | H37: 170.8 | I37: 173.2 | J37: =I37-H37 -> 2.4
A38: Milk and products | B38: 165.4 | C38: 179.6 | D38: =C38-B38 -> 14.2 | E38: 166.4 | F38: 179.4 | G38: =F38-E38 -> 13 | H38: 165.8 | I38: 179.5 | J38: =I38-H38 -> 13.7
A39: Oils and fats | B39: 208.1 | C39: 173.3 | D39: =C39-B39 -> -34.8 | E39: 188.6 | F39: 164.4 | G39: =F39-E39 -> -24.2 | H39: 200.9 | I39: 170 | J39: =I39-H39 -> -30.9
A40: Fruits | B40: 165.8 | C40: 169 | D40: =C40-B40 -> 3.2 | E40: 174.1 | F40: 175.8 | G40: =F40-E40 -> 1.7 | H40: 169.7 | I40: 172.2 | J40: =I40-H40 -> 2.5
A41: Vegetables | B41: 167.3 | C41: 148.7 | D41: =C41-B41 -> -18.6 | E41: 211.5 | F41: 185 | G41: =F41-E41 -> -26.5 | H41: 182.3 | I41: 161 | J41: =I41-H41 -> -21.3
A42: Pulses and products | B42: 164.6 | C42: 174.9 | D42: =C42-B42 -> 10.3 | E42: 163.6 | F42: 176.9 | G42: =F42-E42 -> 13.3 | H42: 164.3 | I42: 175.6 | J42: =I42-H42 -> 11.3
A43: Sugar and Confectionery | B43: 119.1 | C43: 121.9 | D43: =C43-B43 -> 2.8 | E43: 121.4 | F43: 124.2 | G43: =F43-E43 -> 2.8 | H43: 119.9 | I43: 122.7 | J43: =I43-H43 -> 2.8
A44: Spices | B44: 188.9 | C44: 221 | D44: =C44-B44 -> 32.1 | E44: 183.5 | F44: 211.9 | G44: =F44-E44 -> 28.4 | H44: 187.1 | I44: 218 | J44: =I44-H44 -> 30.9
A45: Non-alcoholic beverages | B45: 174.2 | C45: 178.7 | D45: =C45-B45 -> 4.5 | E45: 159.1 | F45: 165.9 | G45: =F45-E45 -> 6.8 | H45: 167.9 | I45: 173.4 | J45: =I45-H45 -> 5.5
...

Sheet PS4
A1: To investigate how the onset and progression of Covid-19 pandemic affected inflation rates in India
C3: Food and beverages | F3: Housing | I3: Fuel and light | L3: Household goods and services | O3: Health | R3: Transport and communication | U3: Recreation and amusement | X3: Education | AA3: Personal care and effects
B4: Month | C4: Rural | D4: Urban | E4: Rural+Urban | F4: Rural | G4: Urban | H4: Rural+Urban | I4: Rural | J4: Urban | K4: Rural+Urban | L4: Rural | M4: Urban | N4: Rural+Urban | O4: Rural | P4: Urban | Q4: Rural+Urban | R4: Rural | S4: Urban | T4: Rural+Urban | U4: Rural | V4: Urban | W4: Rural+Urban | X4: Rural | Y4: Urban | Z4: Rural+Urban | AA4: Rural | AB4: Urban | AC4: Rural+Urban
A5: Before Covid | B5: 43800 | C5: 154.3 | D5: 156.3 | E5: 155 | F5: NA | G5: 152.8 | H5: 152.8 | I5: 149.9 | J5: 133.6 | K5: 143.7 | L5: 151.2 | M5: 139.8 | N5: 145.8 | O5: 154.8 | P5: 143.2 | Q5: 150.4 | R5: 135 | S5: 125.2 | T5: 129.8 | U5: 149.5 | V5: 136.8 | W5: 142.3 | X5: 161.1 | Y5: 151.9 | Z5: 155.7 | AA5: 140.6 | AB5: 140.2 | AC5: 140.4
B6: 43831 | C6: 153 | D6: 154.4 | E6: 153.5 | F6: NA | G6: 153.9 | H6: 153.9 | I6: 150.4 | J6: 135.1 | K6: 144.6 | L6: 151.7 | M6: 140.1 | N6: 146.2 | O6: 155.7 | P6: 143.8 | Q6: 151.2 | R6: 136.3 | S6: 126.1 | T6: 130.9 | U6: 150.1 | V6: 137.2 | W6: 142.8 | X6: 161.7 | Y6: 152.1 | Z6: 156.1 | AA6: 142.5 | AB6: 142.1 | AC6: 142.3
B7: 43862 | C7: 149.8 | D7: 151.7 | E7: 150.5 | F7: NA | G7: 154.8 | H7: 154.8 | I7: 152.3 | J7: 138.9 | K7: 147.2 | L7: 151.8 | M7: 140.4 | N7: 146.4 | O7: 156.2 | P7: 144.4 | Q7: 151.7 | R7: 136 | S7: 125.2 | T7: 130.3 | U7: 150.4 | V7: 137.7 | W7: 143.2 | X7: 161.9 | Y7: 152.2 | Z7: 156.2 | AA7: 143.4 | AB7: 143.5 | AC7: 143.4
A8: Lock Down | B8: 43891 | C8: 148.2 | D8: 150.1 | E8: 148.9 | F8: NA | G8: 154.5 | H8: 154.5 | I8: 153.4 | J8: 141.4 | K8: 148.9 | L8: 151.5 | M8: 140.8 | N8: 146.4 | O8: 156.7 | P8: 145 | Q8: 152.3 | R8: 135.8 | S8: 124.6 | T8: 129.9 | U8: 151.2 | V8: 137.9 | W8: 143.7 | X8: 161.2 | Y8: 152.5 | Z8: 156.1 | AA8: 145.1 | AB8: 145.3 | AC8: 145.2
B9: 43922 | C9: 150.1 | D9: 153.5 | E9: 151.4 | F9: NA | G9: 155.6 | H9: 155.6 | I9: 148.4 | J9: 137.1 | K9: 144.1 | L9: 151.56667 | M9: 140.66667 | N9: 146.4 | O9: 154.3 | P9: 144.8 | Q9: 150.7 | R9: 137.66667 | S9: 126.16667 | T9: 131.6 | U9: 151.86667 | V9: 140.1 | W9: 145.23333 | X9: 161.4 | Y9: 152.5 | Z9: 156.2 | AA9: 147.13333 | AB9: 147.6 | AC9: 147.33333
B10: 43952 | C10: 151.2 | D10: 155.25 | E10: 152.7 | F10: NA | G10: 155.2 | H10: 155.2 | I10: 146.65 | J10: 137.1 | K10: 143 | L10: 151.7 | M10: 140.4 | N10: 146.4 | O10: 156.25 | P10: 146.45 | Q10: 152.55 | R10: 141.4 | S10: 129.3 | T10: 135 | U10: 153.2 | V10: 144.5 | W10: 148.3 | X10: 161.8 | Y10: 152.5 | Z10: 156.4 | AA10: 151.2 | AB10: 152.2 | AC10: 151.6
A11: Post-Covid LockDown | B11: 43983 | C11: 152.3 | D11: 157 | E11: 154 | F11: NA | G11: 154.7 | H11: 154.7 | I11: 144.9 | J11: 137.1 | K11: 141.9 | L11: 151.7 | M11: 140.4 | N11: 146.4 | O11: 158.2 | P11: 148.1 | Q11: 154.4 | R11: 141.4 | S11: 129.3 | T11: 135 | U11: 153.2 | V11: 144.5 | W11: 148.3 | X11: 161.8 | Y11: 152.5 | Z11: 156.4 | AA11: 151.2 | AB11: 152.2 | AC11: 151.6
B12: 44013 | C12: 152.3 | D12: 157 | E12: 154 | F12: NA | G12: 154.7 | H12: 154.7 | I12: 144.9 | J12: 137.1 | K12: 141.9 | L12: 151.7 | M12: 140.4 | N12: 146.4 | O12: 158.2 | P12: 148.1 | Q12: 154.4 | R12: 141.4 | S12: 129.3 | T12: 135 | U12: 153.2 | V12: 144.5 | W12: 148.3 | X12: 161.8 | Y12: 152.5 | Z12: 156.4 | AA12: 151.2 | AB12: 152.2 | AC12: 151.6
B13: 44044 | C13: 155.3 | D13: 159.9 | E13: 157 | F13: NA | G13: 155.5 | H13: 155.5 | I13: 145.8 | J13: 138.3 | K13: 143 | L13: 151.9 | M13: 144.5 | N13: 148.4 | O13: 158.8 | P13: 148.7 | Q13: 155 | R13: 143.6 | S13: 133.9 | T13: 138.5 | U13: 152.2 | V13: 141.2 | W13: 146 | X13: 162.7 | Y13: 155.5 | Z13: 158.5 | AA13: 153.6 | AB13: 155.2 | AC13: 154.3
B14: 44075 | C14: 156.1 | D14: 161.3 | E14: 158 | F14: NA | G14: 156.3 | H14: 156.3 | I14: 146.4 | J14: 137.2 | K14: 142.9 | L14: 151.6 | M14: 145.4 | N14: 148.7 | O14: 159.1 | P14: 150 | Q14: 155.6 | R14: 144.6 | S14: 135.1 | T14: 139.6 | U14: 152.8 | V14: 141.8 | W14: 146.6 | X14: 161.1 | Y14: 154.9 | Z14: 157.5 | AA14: 157.4 | AB14: 159.8 | AC14: 158.4
B15: 44105 | C15: 159.6 | D15: 164.4 | E15: 161.4 | F15: NA | G15: 156.5 | H15: 156.5 | I15: 146.8 | J15: 137.1 | K15: 143.1 | L15: 152 | M15: 145.1 | N15: 148.7 | O15: 159.5 | P15: 151 | Q15: 156.3 | R15: 146.4 | S15: 135.4 | T15: 140.6 | U15: 152.4 | V15: 142 | W15: 146.5 | X15: 162.5 | Y15: 155.7 | Z15: 158.5 | AA15: 156.2 | AB15: 158.1 | AC15: 157
A18: SECTOR : RURAL
B19: Month | C19: Food and beverages | D19: Housing | E19: Fuel and light | F19: Household goods and services | G19: Health | H19: Transport and communication | I19: Recreation and amusement | J19: Education | K19: Personal care and effects
A20: Before Covid | B20: 43800 | C20: =C5/'Cleaned Data'!P245 - 1 -> 0.022531478 | D20: NA | E20: =I5/'Cleaned Data'!V245 - 1 -> 0.010107817 | F20: =L5/'Cleaned Data'!W245 - 1 -> 0.0019880716 | G20: =O5/'Cleaned Data'!X245 - 1 -> 0.0032404407 | H20: =R5/'Cleaned Data'!Y245 - 1 -> 0.021953066 | I20: =U5/'Cleaned Data'!Z245 - 1 -> 0.0026827632 | J20: =X5/'Cleaned Data'!AA245 - 1 -> 0.0018656716 | K20: =AA5/'Cleaned Data'!AB245 - 1 -> 0
B21: 43831 | C21: =C6/C5 - 1 -> -0.0084251458 | D21: NA | E21: =I6/I5 - 1 -> 0.003335557 | F21: =L6/L5 - 1 -> 0.0033068783 | G21: =O6/O5 - 1 -> 0.0058139535 | H21: =R6/R5 - 1 -> 0.0096296296 | I21: =U6/U5 - 1 -> 0.0040133779 | J21: =X6/X5 - 1 -> 0.0037243948 | K21: =AA6/AA5 - 1 -> 0.013513514
B22: 43862 | C22: =C7/C6 - 1 -> -0.020915033 | D22: NA | E22: =I7/I6 - 1 -> 0.012632979 | F22: =L7/L6 - 1 -> 0.00065919578 | G22: =O7/O6 - 1 -> 0.0032113038 | H22: =R7/R6 - 1 -> -0.0022010271 | I22: =U7/U6 - 1 -> 0.0019986676 | J22: =X7/X6 - 1 -> 0.0012368584 | K22: =AA7/AA6 - 1 -> 0.0063157895
A23: Lock Down | B23: 43891 | C23: =C8/C7 - 1 -> -0.010680908 | D23: NA | E23: =I8/I7 - 1 -> 0.007222587 | F23: =L8/L7 - 1 -> -0.0019762846 | G23: =O8/O7 - 1 -> 0.0032010243 | H23: =R8/R7 - 1 -> -0.0014705882 | I23: =U8/U7 - 1 -> 0.0053191489 | J23: =X8/X7 - 1 -> -0.0043236566 | K23: =AA8/AA7 - 1 -> 0.011854951
B24: 43922 | C24: =C9/C8 - 1 -> 0.012820513 | D24: NA | E24: =I9/I8 - 1 -> -0.032594524 | F24: =L9/L8 - 1 -> 0.000440044 | G24: =O9/O8 - 1 -> -0.01531589 | H24: =R9/R8 - 1 -> 0.013745704 | I24: =U9/U8 - 1 -> 0.0044091711 | J24: =X9/X8 - 1 -> 0.0012406948 | K24: =AA9/AA8 - 1 -> 0.014013324
B25: 43952 | C25: =C10/C9 - 1 -> 0.0073284477 | D25: NA | E25: =I10/I9 - 1 -> -0.011792453 | F25: =L10/L9 - 1 -> 0.0008797009 | G25: =O10/O9 - 1 -> 0.012637719 | H25: =R10/R9 - 1 -> 0.027118644 | I25: =U10/U9 - 1 -> 0.0087796313 | J25: =X10/X9 - 1 -> 0.0024783147 | K25: =AA10/AA9 - 1 -> 0.027639329
A26: Post-Covid LockDown | B26: 43983 | C26: =C11/C10 - 1 -> 0.0072751323 | D26: NA | E26: =I11/I10 - 1 -> -0.011933174 | F26: =L11/L10 - 1 -> 0 | G26: =O11/O10 - 1 -> 0.01248 | H26: =R11/R10 - 1 -> 0 | I26: =U11/U10 - 1 -> 0 | J26: =X11/X10 - 1 -> 0 | K26: =AA11/AA10 - 1 -> 0
B27: 44013 | C27: =C12/C11 - 1 -> 0 | D27: NA | E27: =I12/I11 - 1 -> 0 | F27: =L12/L11 - 1 -> 0 | G27: =O12/O11 - 1 -> 0 | H27: =R12/R11 - 1 -> 0 | I27: =U12/U11 - 1 -> 0 | J27: =X12/X11 - 1 -> 0 | K27: =AA12/AA11 - 1 -> 0
B28: 44044 | C28: =C13/C12 - 1 -> 0.019697965 | D28: NA | E28: =I13/I12 - 1 -> 0.0062111801 | F28: =L13/L12 - 1 -> 0.0013183916 | G28: =O13/O12 - 1 -> 0.0037926675 | H28: =R13/R12 - 1 -> 0.015558699 | I28: =U13/U12 - 1 -> -0.0065274151 | J28: =X13/X12 - 1 -> 0.0055624227 | K28: =AA13/AA12 - 1 -> 0.015873016
B29: 44075 | C29: =C14/C13 - 1 -> 0.00515132 | D29: NA | E29: =I14/I13 - 1 -> 0.0041152263 | F29: =L14/L13 - 1 -> -0.0019749835 | G29: =O14/O13 - 1 -> 0.0018891688 | H29: =R14/R13 - 1 -> 0.0069637883 | I29: =U14/U13 - 1 -> 0.0039421813 | J29: =X14/X13 - 1 -> -0.0098340504 | K29: =AA14/AA13 - 1 -> 0.024739583
B30: 44105 | C30: =C15/C14 - 1 -> 0.022421525 | D30: NA | E30: =I15/I14 - 1 -> 0.0027322404 | F30: =L15/L14 - 1 -> 0.0026385224 | G30: =O15/O14 - 1 -> 0.002514142 | H30: =R15/R14 - 1 -> 0.012448133 | I30: =U15/U14 - 1 -> -0.002617801 | J30: =X15/X14 - 1 -> 0.0086902545 | K30: =AA15/AA14 - 1 -> -0.0076238882
A32: SECTOR : URBAN
B33: Month | C33: Food and beverages | D33: Housing | E33: Fuel and light | F33: Household goods and services | G33: Health | H33: Transport and communication | I33: Recreation and amusement | J33: Education | K33: Personal care and effects
A34: Before Covid | B34: 43800 | C34: =D5/'Cleaned Data'!P246 - 1 -> 0.017578125 | D34: =G5/'Cleaned Data'!U246 - 1 -> -0.0045602606 | E34: =J5/'Cleaned Data'!V246 - 1 -> 0.010590015 | F34: =M5/'Cleaned Data'!W246-1 -> 0.0050323508 | G34: =P5/'Cleaned Data'!X246-1 -> 0.0028011204 | H34: =S5/'Cleaned Data'!Y246-1 -> 0.028759244 | I34: =V5/'Cleaned Data'!Z246-1 -> 0.0007315289 | J34: =Y5/'Cleaned Data'!AA246-1 -> 0.00065876153 | K34: =AB5/'Cleaned Data'!AB246-1 -> 0.0028612303
B35: 43831 | C35: =D6/D5 -1 -> -0.01215611 | D35: =G6/65 - 1 -> 1.3676923 | E35: =J6/J5 - 1 -> 0.011227545 | F35: =M6/M5 - 1 -> 0.0021459227 | G35: =P6/P5 - 1 -> 0.0041899441 | H35: =S6/S5 - 1 -> 0.0071884984 | I35: =V6/V5 - 1 -> 0.0029239766 | J35: =Y6/Y5 - 1 -> 0.0013166557 | K35: =AB6/AB5 - 1 -> 0.013552068
B36: 43862 | C36: =D7/D6 -1 -> -0.017487047 | D36: =G7/65 - 1 -> 1.3815385 | E36: =J7/J6 - 1 -> 0.028127313 | F36: =M7/M6 - 1 -> 0.0021413276 | G36: =P7/P6 - 1 -> 0.0041724618 | H36: =S7/S6 - 1 -> -0.0071371927 | I36: =V7/V6 - 1 -> 0.0036443149 | J36: =Y7/Y6 - 1 -> 0.0006574622 | K36: =AB7/AB6 - 1 -> 0.0098522167
A37: Lock Down | B37: 43891 | C37: =D8/D7 -1 -> -0.010547132 | D37: =G8/65 - 1 -> 1.3769231 | E37: =J8/J7 - 1 -> 0.01799856 | F37: =M8/M7 - 1 -> 0.0028490028 | G37: =P8/P7 - 1 -> 0.0041551247 | H37: =S8/S7 - 1 -> -0.0047923323 | I37: =V8/V7 - 1 -> 0.0014524328 | J37: =Y8/Y7 - 1 -> 0.0019710907 | K37: =AB8/AB7 - 1 -> 0.012543554
B38: 43922 | C38: =D9/D8 -1 -> 0.022651566 | D38: =G9/65 - 1 -> 1.3938462 | E38: =J9/J8 - 1 -> -0.030410184 | F38: =M9/M8 - 1 -> -0.0009469697 | G38: =P9/P8 - 1 -> -0.0013793103 | H38: =S9/S8 - 1 -> 0.012573569 | I38: =V9/V8 - 1 -> 0.01595359 | J38: =Y9/Y8 - 1 -> 0 | K38: =AB9/AB8 - 1 -> 0.015829319
B39: 43952 | C39: =D10/D9 -1 -> 0.011400651 | D39: =G10/65 - 1 -> 1.3876923 | E39: =J10/J9 - 1 -> 0 | F39: =M10/M9 - 1 -> -0.0018957346 | G39: =P10/P9 - 1 -> 0.011395028 | H39: =S10/S9 - 1 -> 0.024834875 | I39: =V10/V9 - 1 -> 0.031406138 | J39: =Y10/Y9 - 1 -> 0 | K39: =AB10/AB9 - 1 -> 0.031165312
A40: Post-Covid LockDown | B40: 43983 | C40: =D11/D10 -1 -> 0.011272142 | D40: =G11/65 - 1 -> 1.38 | E40: =J11/J10 - 1 -> 0 | F40: =M11/M10 - 1 -> 0 | G40: =P11/P10 - 1 -> 0.011266644 | H40: =S11/S10 - 1 -> 0 | I40: =V11/V10 - 1 -> 0 | J40: =Y11/Y10 - 1 -> 0 | K40: =AB11/AB10 - 1 -> 0
B41: 44013 | C41: =D12/D11 -1 -> 0 | D41: =G12/65 - 1 -> 1.38 | E41: =J12/J11 - 1 -> 0 | F41: =M12/M11 - 1 -> 0 | G41: =P12/P11 - 1 -> 0 | H41: =S12/S11 - 1 -> 0 | I41: =V12/V11 - 1 -> 0 | J41: =Y12/Y11 - 1 -> 0 | K41: =AB12/AB11 - 1 -> 0
B42: 44044 | C42: =D13/D12 -1 -> 0.018471338 | D42: =G13/65 - 1 -> 1.3923077 | E42: =J13/J12 - 1 -> 0.0087527352 | F42: =M13/M12 - 1 -> 0.029202279 | G42: =P13/P12 - 1 -> 0.0040513167 | H42: =S13/S12 - 1 -> 0.035576179 | I42: =V13/V12 - 1 -> -0.02283737 | J42: =Y13/Y12 - 1 -> 0.019672131 | K42: =AB13/AB12 - 1 -> 0.019710907
B43: 44075 | C43: =D14/D13 -1 -> 0.0087554722 | D43: =G14/65 - 1 -> 1.4046154 | E43: =J14/J13 - 1 -> -0.0079537238 | F43: =M14/M13 - 1 -> 0.0062283737 | G43: =P14/P13 - 1 -> 0.0087424344 | H43: =S14/S13 - 1 -> 0.0089619119 | I43: =V14/V13 - 1 -> 0.0042492918 | J43: =Y14/Y13 - 1 -> -0.0038585209 | K43: =AB14/AB13 - 1 -> 0.029639175
B44: 44105 | C44: =D15/D14 -1 -> 0.019218847 | D44: =G15/65 - 1 -> 1.4076923 | E44: =J15/J14 - 1 -> -0.00072886297 | F44: =M15/M14 - 1 -> -0.0020632737 | G44: =P15/P14 - 1 -> 0.0066666667 | H44: =S15/S14 - 1 -> 0.0022205774 | I44: =V15/V14 - 1 -> 0.0014104372 | J44: =Y15/Y14 - 1 -> 0.0051646223 | K44: =AB15/AB14 - 1 -> -0.010638298
...

Sheet PS5
A1: To Investigate how major global economic events (like imported crude oil price fluctuations) have influenced India's inflation.
A2: INFLATION
A3: Month-Year | B3: Price | C3: Food and Beverages | D3: Fuel and Light | E3: Transport and Communication | F3: Others | H3: Category | I3: Correlation
A4: 44317 | B4: 0 | C4: 0 | D4: 0 | E4: 0 | F4: 0 | H4: Food and Beverages | I4: =CORREL($B$5:$B$28,$C$5:$C$28) -> -0.0040586325
A5: 44348 | B5: ='Imported Oil Prices'!B4/'Imported Oil Prices'!B3-1 -> 0.068208761 | C5: ='Imported Oil Prices'!C4/'Imported Oil Prices'!C3-1 -> 0.011823273 | D5: ='Imported Oil Prices'!D4/'Imported Oil Prices'!D3-1 -> 0.0025094103 | E5: ='Imported Oil Prices'!E4/'Imported Oil Prices'!E3-1 -> 0.01208865 | F5: ='Imported Oil Prices'!F4/'Imported Oil Prices'!F3-1 -> -0.0017409471 | H5: Fuel and Light | I5: =CORREL($B$5:$B$28,$D$5:$D$28) -> -0.075638543
A6: 44378 | B6: ='Imported Oil Prices'!B5/'Imported Oil Prices'!B4-1 -> -0.0055224861 | C6: ='Imported Oil Prices'!C5/'Imported Oil Prices'!C4-1 -> 0.0086100861 | D6: ='Imported Oil Prices'!D5/'Imported Oil Prices'!D4-1 -> 0.0056320401 | E6: ='Imported Oil Prices'!E5/'Imported Oil Prices'!E4-1 -> 0.01592568 | F6: ='Imported Oil Prices'!F5/'Imported Oil Prices'!F4-1 -> 0.004795954 | H6: Transport and Communication | I6: =CORREL($B$5:$B$28,$E$5:$E$28) -> 0.15330026
A7: 44409 | B7: ='Imported Oil Prices'!B6/'Imported Oil Prices'!B5-1 -> -0.036768356 | C7: ='Imported Oil Prices'!C6/'Imported Oil Prices'!C5-1 -> 0 | D7: ='Imported Oil Prices'!D6/'Imported Oil Prices'!D5-1 -> 0.011823273 | E7: ='Imported Oil Prices'!E6/'Imported Oil Prices'!E5-1 -> 0.0058785108 | F7: ='Imported Oil Prices'!F6/'Imported Oil Prices'!F5-1 -> 0.0074633342 | H7: Others | I7: =CORREL($B$5:$B$28,$F$5:$F$28) -> -0.074202608
A8: 44440 | B8: ='Imported Oil Prices'!B7/'Imported Oil Prices'!B6-1 -> 0.055560572 | C8: ='Imported Oil Prices'!C7/'Imported Oil Prices'!C6-1 -> 0 | D8: ='Imported Oil Prices'!D7/'Imported Oil Prices'!D6-1 -> 0 | E8: ='Imported Oil Prices'!E7/'Imported Oil Prices'!E6-1 -> 0 | F8: ='Imported Oil Prices'!F7/'Imported Oil Prices'!F6-1 -> 0.00017228013
A9: 44470 | B9: ='Imported Oil Prices'!B8/'Imported Oil Prices'!B7-1 -> 0.091262761 | C9: ='Imported Oil Prices'!C8/'Imported Oil Prices'!C7-1 -> 0.022560976 | D9: ='Imported Oil Prices'!D8/'Imported Oil Prices'!D7-1 -> 0.0098400984 | E9: ='Imported Oil Prices'!E8/'Imported Oil Prices'!E7-1 -> 0.011038961 | F9: ='Imported Oil Prices'!F8/'Imported Oil Prices'!F7-1 -> 0.0055120145
A10: 44501 | B10: ='Imported Oil Prices'!B9/'Imported Oil Prices'!B8-1 -> -0.066879657 | C10: ='Imported Oil Prices'!C9/'Imported Oil Prices'!C8-1 -> 0.011926058 | D10: ='Imported Oil Prices'!D9/'Imported Oil Prices'!D8-1 -> -0.0018270402 | E10: ='Imported Oil Prices'!E9/'Imported Oil Prices'!E8-1 -> -0.0057803468 | F10: ='Imported Oil Prices'!F9/'Imported Oil Prices'!F8-1 -> 0.0056531049
A11: 44531 | B11: ='Imported Oil Prices'!B10/'Imported Oil Prices'!B9-1 -> -0.017844285 | C11: ='Imported Oil Prices'!C10/'Imported Oil Prices'!C9-1 -> -0.0088391279 | D11: ='Imported Oil Prices'!D10/'Imported Oil Prices'!D9-1 -> 0.0012202563 | E11: ='Imported Oil Prices'!E10/'Imported Oil Prices'!E9-1 -> 0.0058139535 | F11: ='Imported Oil Prices'!F10/'Imported Oil Prices'!F9-1 -> 0.0022996338
A12: 44562 | B12: ='Imported Oil Prices'!B11/'Imported Oil Prices'!B10-1 -> 0.27358776 | C12: ='Imported Oil Prices'!C11/'Imported Oil Prices'!C10-1 -> -0.010701546 | D12: ='Imported Oil Prices'!D11/'Imported Oil Prices'!D10-1 -> 0.00060938452 | E12: ='Imported Oil Prices'!E11/'Imported Oil Prices'!E10-1 -> 0.0051380861 | F12: ='Imported Oil Prices'!F11/'Imported Oil Prices'!F10-1 -> 0.0043337865
